Workbook

Sheet 0_README
A1: DAY 28 — MONETIZATION MODEL
A2: AI Pricing · GTM · Evidence — AI-IN-ACTION Track 1
A4: QUY ƯỚC MÀU — CHỈ ĐIỀN VÀO Ô MÀU VÀNG
A5: Ô VÀNG, chữ xanh dương | B5: Ô bạn phải điền
A6: Ô XÁM, chữ đen | B6: Công thức tự tính — KHÔNG SỬA
A7: Chữ xanh lá | B7: Link sang tab khác
A8: Ô XÁM đậm nhạt | B8: Bảng tham chiếu, chỉ đọc
A10: THỨ TỰ LÀM — 6 TRẠM, 120 PHÚT
A11: Trạm 1 · 15' | B11: Ngân sách khách & định nghĩa Job → điền S1–S2 của tab 1_Cost_Job
A12: Trạm 2 · 20' | B12: Value Metric → tab 3_Value_Metric
A13: Trạm 3 · 30' | B13: Cost/Job, giá sàn & giá trần → tab 1_Cost_Job (S3–S8) rồi 2_Pricing
A14: Trạm 4 · 20' | B14: Kênh phân phối & Affordability Test → tab 4_Channel_Fit
A15: Trạm 5 · 15' | B15: Pain Moment & 90-Day Plan → tab 5_90Day_Plan
A16: Trạm 6 · 20' | B16: Evidence Pack & ráp One-Pager → tab 5_90Day_Plan + file .docx
A18: 3 QUY TẮC KHÔNG ĐƯỢC PHÁ
A19: 1. Chia cho số job HOÀN THÀNH, không phải số job đã thử.
A20: 2. HITL và Retry không được để 0 nếu không có lý do viết ra được.
A21: 3. Mọi con số giá API phải có NGÀY kiểm tra (xem tab 6_Benchmarks).
A23: Giá tham chiếu trong workbook này được chốt ngày 26/08/2026. Nhiều mức giá là KHUYẾN MẠI CÓ HẠN.
A24: Bạn PHẢI tự mở lại trang giá của nhà cung cấp và cập nhật — đây là một phần của bài tập.

Sheet 1_Cost_Job
A1: TAB 1 — COST/JOB CALCULATOR
A2: Trạm 1 (S1–S2) và Trạm 3 (S3–S8). Chỉ điền ô vàng.
A4: S1. ĐỊNH NGHĨA JOB
A5: 1 job của bạn là gì? | B5: 1 lịch bảo dưỡng xe VinFast được xác nhận thành công (booking status = CONFIRMED, có SMS xác nhận cho khách và ghi nhận vào lịch kỹ thuật viên đại lý) | D5: Phải là thứ KHÁCH coi là giá trị — không phải '1 request'
A6: Biến thể HITL: A hay B? | B6: A | D6: A = khách tự xử lý ca escalate · B = BẠN chịu (outcome/managed)
A8: S2. KHỐI LƯỢNG
A9: Số job THỬ / tháng | B9: 500 | C9: job
A10: Containment rate (AI tự làm xong) | B10: 0.8 | D10: Chưa đo → ước tính và ghi rõ
A11: → Số job HOÀN THÀNH / tháng | B11: =B9*B10 | C11: job | D11: MẪU SỐ của Cost/Job
A12: → Số job KHÔNG xong / tháng | B12: =B9-B11 | C12: job | D12: Số ca phải escalate
A14: S3. API — LLM
A15: Giá input ($ / 1M token) | B15: 1 | D15: Claude Haiku 4.5 — xem tab 6_Benchmarks
A16: Giá output ($ / 1M token) | B16: 5
A17: Giá cache WRITE ($ / 1M token) | B17: 1.25 | D17: Anthropic 5-phút = 1,25× input
A18: Giá cache READ ($ / 1M token) | B18: 0.1 | D18: ≈ 0,1× input (giảm 90%)
A19: Số lượt (turns) / job | B19: 5 | C19: lượt
A20: Token input CACHE ĐƯỢC / lượt | B20: 2800 | C20: token | D20: System prompt + KB + few-shot
A21: Token input FRESH / lượt | B21: 700 | C21: token | D21: Câu hỏi khách + dữ liệu động
A22: Token output / lượt | B22: 250 | C22: token
A23: → Cache write / job | B23: =B20*B17/1000000
A24: → Cache read / job | B24: =(B19-1)*B20*B18/1000000
A25: → Input fresh / job | B25: =B19*B21*B15/1000000
A26: → Output / job | B26: =B19*B22*B16/1000000
A27: → LLM / job — CÓ prompt caching | B27: =SUM(B23:B26)
A28: → LLM / job — KHÔNG cache | B28: =B19*(B20+B21)*B15/1000000+B26
A29: → % tiết kiệm nhờ caching | B29: =IF(B28=0,0,1-B27/B28) | D29: Đòn bẩy rẻ nhất bạn có
A30: Dùng Batch API? (1 = có, 0 = không) | B30: 0 | D30: Batch giảm 50% — chỉ khi job KHÔNG cần realtime
A31: → LLM / job sau Batch | B31: =B27*(1-B30*0.5)
A33: S4. API — SPEECH (để 0 nếu sản phẩm không có thoại)
A34: Giá STT ($ / phút) | B34: 0 | D34: Deepgram streaming list $0,0077/phút
A35: Số phút audio / job | B35: 0 | C35: phút
A36: Giá TTS ($ / 1M ký tự) | B36: 0 | D36: ElevenLabs Flash $50 · Google Standard $4
A37: Số ký tự TTS / job | B37: 0 | C37: ký tự | D37: ≈ 900 ký tự cho mỗi phút bot nói
A38: → Speech / job | B38: =B34*B35+B36*B37/1000000
A40: S5. INFRA
A41: Infra / job ($) | B41: 0.0836 | D41: Vector DB, embedding, storage, logging
A42: Telephony ($ / phút) | B42: 0
A43: → Infra / job | B43: =B41+B42*B35
A45: S6. RETRY
A46: Tỷ lệ job phải chạy lại | B46: 0.07 | D46: ĐỪNG để 0%. Thực tế 5–10% là bình thường
...

Sheet 2_Pricing
A1: TAB 2 — PRICING SANITY CHECK
A2: Trạm 3. Cost/Job tự lấy từ tab 1. Bạn điền giá bán và các con số neo giá.
A4: GIÁ SÀN
A5: Cost/Job (từ tab 1_Cost_Job) | B5: ='1_Cost_Job'!B66 | C5: $/job
A6: Hệ số an toàn tối thiểu | B6: 3 | C6: × | D6: Giá bán ≥ 3 × Cost/Job
A7: → GIÁ SÀN | B7: =B5*B6 | C7: $/job
A9: GIÁ TRẦN — NEO THEO THỨ KHÁCH ĐANG CHI
A10: Giá trị khách tiết kiệm được / tháng ($) | B10: 2500 | D10: Neo theo giá trị
A11: Số job / tháng của 1 khách | B11: 400 | C11: job
A12: → Trần theo giá trị — mức 10% | B12: =IF(B11=0,0,B10*0.1/B11) | C12: $/job
A13: → Trần theo giá trị — mức 25% | B13: =IF(B11=0,0,B10*0.25/B11) | C13: $/job
A14: Lương / tháng của vị trí bị thay ($) | B14: 800 | D14: Neo theo nhân công
A15: → Trần theo nhân công — mức 50% | B15: =IF(B11=0,0,B14*0.5/B11) | C15: $/job
A16: → Trần theo nhân công — mức 70% | B16: =IF(B11=0,0,B14*0.7/B11) | C16: $/job
A18: GIÁ BÁN CỦA BẠN
A19: ★ Giá bán đề xuất ($ / job) | B19: 1.378 | C19: $/job | D19: Tham chiếu: Intercom Fin $0,99 · Zendesk $1,50
A20: → Bội số so với Cost/Job | B20: =IF(B5=0,0,B19/B5)
A21: → GROSS MARGIN | B21: =IF(B19=0,0,(B19-B5)/B19)
A22: → Đèn: bội số ≥ 3? | B22: =IF(B20>=B6,"OK — ĐẠT","KHÔNG ĐẠT — quay lại tab 1")
A23: → Đèn: Gross Margin | B23: =IF(B21>=0.6,"OK — AN TOÀN (≥60%)",IF(B21>=0.5,"CẢNH BÁO (50–60%)","NGUY HIỂM (<50%)"))
A24: → Đèn: GM có cao bất thường? | B24: =IF(B21>0.85,"NGHI NGỜ — nhiều khả năng bạn quên một khoản chi phí","OK")
A25: → Giá bán nằm trong vùng neo? | B25: =IF(AND(B19>=B7,B19<=MAX(B13,B16)),"OK — trong vùng giá bán","XEM LẠI — ngoài vùng giá sàn/trần")
A27: BREAKEVEN CONTAINMENT — ngưỡng sống còn
A28: Ký hiệu: v = chi phí biến đổi / job thử · q = QA / job thử · e = chi phí 1 ca escalate
A29: v — chi phí biến đổi / job thử | B29: ='1_Cost_Job'!B31+'1_Cost_Job'!B38+'1_Cost_Job'!B43+'1_Cost_Job'!B47
A30: q — QA nội bộ / job thử | B30: ='1_Cost_Job'!B51*('1_Cost_Job'!B52/60)*'1_Cost_Job'!B50
A31: e — chi phí 1 ca escalate | B31: =IF('1_Cost_Job'!B6="B",('1_Cost_Job'!B53/60)*'1_Cost_Job'!B50,0)
A32: Gross Margin mục tiêu | B32: 0.6
A33: ★ Containment tối thiểu cần đạt | B33: =IF((B19*(1-B32)+B31)=0,0,(B29+B30+B31)/(B19*(1-B32)+B31)) | D33: Công thức: R ≥ (v+q+e) / (P×(1−GM)+e)
A34: Containment hiện tại (từ tab 1) | B34: ='1_Cost_Job'!B10
A35: → Kết luận | B35: =IF(B34>=B33,"ĐẠT — mô hình có lãi lành mạnh","CHƯA ĐẠT — phải tăng containment, tăng giá, hoặc đổi biến thể HITL")
A37: SENSITIVITY — mô hình gãy ở đâu?
A38: Containment | B38: Cost/Job | C38: Gross Margin | D38: Đánh giá
A39: 0.5 | B39: =($B$29+$B$30+$B$31*(1-A39))/A39 | C39: =IF($B$19=0,0,1-B39/$B$19) | D39: =IF(C39>=0.6,"An toàn",IF(C39>=0.5,"Cảnh báo","Nguy hiểm"))
A40: 0.6 | B40: =($B$29+$B$30+$B$31*(1-A40))/A40 | C40: =IF($B$19=0,0,1-B40/$B$19) | D40: =IF(C40>=0.6,"An toàn",IF(C40>=0.5,"Cảnh báo","Nguy hiểm"))
A41: 0.7 | B41: =($B$29+$B$30+$B$31*(1-A41))/A41 | C41: =IF($B$19=0,0,1-B41/$B$19) | D41: =IF(C41>=0.6,"An toàn",IF(C41>=0.5,"Cảnh báo","Nguy hiểm"))
A42: 0.8 | B42: =($B$29+$B$30+$B$31*(1-A42))/A42 | C42: =IF($B$19=0,0,1-B42/$B$19) | D42: =IF(C42>=0.6,"An toàn",IF(C42>=0.5,"Cảnh báo","Nguy hiểm"))
A43: 0.9 | B43: =($B$29+$B$30+$B$31*(1-A43))/A43 | C43: =IF($B$19=0,0,1-B43/$B$19) | D43: =IF(C43>=0.6,"An toàn",IF(C43>=0.5,"Cảnh báo","Nguy hiểm"))
A44: 0.95 | B44: =($B$29+$B$30+$B$31*(1-A44))/A44 | C44: =IF($B$19=0,0,1-B44/$B$19) | D44: =IF(C44>=0.6,"An toàn",IF(C44>=0.5,"Cảnh báo","Nguy hiểm"))
A46: Nhìn cột Gross Margin: mô hình của bạn mong manh đến mức nào khi AI làm sai nhiều hơn dự kiến?
...

Sheet 3_Value_Metric
A1: TAB 3 — VALUE METRIC SCORECARD
A2: Trạm 2. Chấm 0 / 1 / 2 điểm cho mỗi câu, theo THỰC TẾ HÔM NAY.
A4: A. ATTRIBUTION — bạn đo được kết quả là do AI tạo ra không?
A5: 1. Tôi có log đầy đủ mỗi job AI xử lý, gắn được với kết quả cuối cùng | B5: 2
A6: 2. Tôi có bộ eval đo được tỷ lệ AI làm đúng, có số liệu | B6: 2
A7: 3. Khách hàng đồng ý với cách tôi định nghĩa 'thành công' của một job | B7: 2
A8: 4. Tôi phân biệt được kết quả do AI tạo ra với kết quả do yếu tố khác | B8: 1
A9: 5. Tôi viết được định nghĩa chặt như Intercom: cái gì tính tiền, cái gì không | B9: 2
A10: → ĐIỂM ATTRIBUTION (tối đa 10) | B10: =SUM(B5:B9)
A12: B. AUTONOMY — AI tự chạy hay cần người?
A13: 1. AI hoàn thành job từ đầu đến cuối, không cần người bấm nút giữa chừng | B13: 2
A14: 2. Job chạy được ngoài giờ hành chính mà không ai trực | B14: 2
A15: 3. Khi AI không chắc, nó tự chuyển tiếp đúng chỗ — không cần người phân loại | B15: 2
A16: 4. Tỷ lệ ca phải có người can thiệp dưới 20% | B16: 2
A17: 5. Người vận hành chỉ kiểm tra mẫu (QA), không xử lý từng ca | B17: 1
A18: → ĐIỂM AUTONOMY (tối đa 10) | B18: =SUM(B13:B17)
A20: GỢI Ý CỦA MODEL
A21: → Value Metric gợi ý | B21: =IF(AND(B10>=7,B18>=7),"OUTCOME",IF(AND(B10>=7,B18<7),"USAGE",IF(AND(B10<7,B18>=7),"USAGE (an toàn)","SEAT hoặc HYBRID")))
A22: Ngưỡng 7/10 là quy ước của bài tập, không phải chuẩn ngành — dùng để buộc bạn ra quyết định, không phải để thay bạn quyết định.
A24: BENCHMARK NGƯỢC — 2 sản phẩm thật cùng loại job
A25: Tên sản phẩm | B25: Value Metric | C25: Giá công bố | D25: Link nguồn
A26: Intercom Fin | B26: Outcome (Resolution) | C26: $0,99 / resolution | D26: https://fin.ai/pricing/
A27: Salesforce Agentforce | B27: Hybrid (Platform fee + per Action) | C27: $5/user/tháng + $0,10/action | D27: https://salesforce.com/agentforce/pricing/
A29: QUYẾT ĐỊNH CUỐI
A30: Value Metric tôi chọn | B30: Hybrid
A31: Nếu KHÁC gợi ý — lý do thị trường là gì? | B31: Thị trường đại lý ô tô tại Việt Nam chưa quen trả 100% outcome thuần do ngại rủi ro biến động chi phí. Mô hình Hybrid (phí nền 1.500.000₫/tháng + 20.000₫/booking confirmed) giúp đại lý dễ lập kế hoạch ngân sách hàng tháng, đồng thời bảo đảm dòng tiền bù đắp chi phí cố định (server, DB, support) cho startup ngay từ những tháng đầu.
A32: Decision Note — câu 1: tôi chọn đơn vị nào? | B32: Tôi chọn mô hình Hybrid gồm phí nền cố định 1.500.000₫/tháng/đại lý kết hợp 20.000₫/lịch bảo dưỡng xác nhận thành công (booking status = CONFIRMED).
A33: Decision Note — câu 2: bằng chứng Attribution / Autonomy? | B33: Điểm Attribution đạt 9/10 (log minh bạch mã booking trên DMS và SMS brandname gửi thành công) và Autonomy đạt 9/10 (AI tự động 80% quy trình 24/7 theo smoke test 50 ca).
A34: Decision Note — câu 3: mô hình này lỗ trong tình huống nào? | B34: Mô hình này lỗ khi tỷ lệ containment tụt dưới 30,5% kết hợp số lượng đại lý dưới 3, khiến doanh thu không bù nổi chi phí nhân sự QA và hạ tầng cố định.

Sheet 4_Channel_Fit
A1: TAB 4 — CHANNEL FIT & AFFORDABILITY TEST
A2: Trạm 4. Chọn ĐÚNG 1 kênh cho 90 ngày đầu — và chứng minh bằng số.
A4: A. NGÂN SÁCH CAC — bạn nuôi nổi kênh nào?
A5: ARPU / tháng ($) | B5: 374
A6: Gross Margin (từ tab 2_Pricing) | B6: ='2_Pricing'!B21
A7: Phân khúc (SMB / Mid / Enterprise) | B7: SMB
A8: → CAC payback cho phép (tháng) | B8: =IF(B7="SMB",12,IF(B7="Mid",18,24)) | C8: tháng | D8: Bessemer, Scaling to $100M (2024)
A9: ★ NGÂN SÁCH CAC / khách | B9: =B5*B6*B8 | D9: ARPU × GM × số tháng payback
A10: → ACV (giá trị hợp đồng / năm) | B10: =B5*12
A12: B. SALES VIABILITY — một AE phải chốt bao nhiêu deal?
A13: Quota / AE / năm ($) | B13: 500000 | D13: Giả định gốc của Tunguz (2016) — thay bằng số thị trường bạn
A14: Số ngày làm việc / năm | B14: 250 | C14: ngày
A15: → Số deal / AE / năm | B15: =IF(B10=0,0,B13/B10)
A16: ★ Số deal / AE / NGÀY | B16: =IF(B14=0,0,B15/B14) | C16: deal/ngày
A17: → Kết luận Sales-Led | B17: =IF(B16<=1,"KHẢ THI về mặt số học","BẤT KHẢ THI — ACV quá thấp để nuôi sales rep")
A19: C. ĐỐI CHIẾU CAC THỰC TẾ CỦA MOTION CÓ SALES
A20: Cost per opportunity ($) | B20: 8000 | D20: ICONIQ 2026 theo phân khúc: $6.300 · $8.000 · $11.200
A21: Win rate | B21: 0.25
A22: → CAC thực tế ước tính / khách | B22: =IF(B21=0,0,B20/B21)
A23: ★ Lệch bao nhiêu lần so với ngân sách CAC? | B23: =IF(B9=0,0,B22/B9) | D23: Đây là bằng chứng chọn kênh của bạn
A24: → Kết luận | B24: =IF(B23<=1,"Motion có sales KHẢ THI",IF(B23<=3,"Căng — cần tăng giá hoặc giảm chi phí bán hàng","KHÔNG KHẢ THI — đi PLG hoặc Partner-Led"))
A26: D. CHẤM ĐIỂM 3 KÊNH (1 = rất kém, 5 = rất tốt)
A27: Tiêu chí | B27: PLG | C27: Sales-Led | D27: Partner-Led
A28: 1. Ngân sách CAC của tôi nuôi nổi kênh này | B28: 4 | C28: 1 | D28: 5
A29: 2. Khách hàng mục tiêu thực sự mua theo cách này | B29: 2 | C29: 3 | D29: 5
A30: 3. Đội hiện tại có năng lực chạy kênh này ngay | B30: 2 | C30: 2 | D30: 4
A31: 4. Tôi tiếp cận được điểm nhúng / partner trong 30 ngày | B31: 2 | C31: 2 | D31: 4
A32: 5. Kênh này đưa tôi đến ĐÚNG Pain Moment | B32: 3 | C32: 3 | D32: 5
A33: 6. Tôi đo được hiệu quả trong vòng 90 ngày | B33: 3 | C33: 2 | D33: 5
A34: → TỔNG ĐIỂM | B34: =SUM(B28:B33) | C34: =SUM(C28:C33) | D34: =SUM(D28:D33)
A35: → Kênh điểm cao nhất | B35: =IF(AND(B34>=C34,B34>=D34),"PLG",IF(C34>=D34,"Sales-Led","Partner-Led"))
A37: E. CHỐT KÊNH
A38: ★ Kênh tôi chọn cho 90 ngày đầu | B38: Partner-Led | D38: ĐÚNG 1 kênh. Chọn 2 kênh trở lên bị trừ điểm.
A39: Nếu Partner-Led: TÊN CÔNG TY partner | B39: VinFast Vietnam (Bộ phận Dịch vụ Hậu mãi & Mạng lưới Đại lý - Aftersales & Dealer Network) | D39: 'Các nền tảng trong ngành' = chưa có kênh
A40: Đã nói chuyện với họ chưa? (Rồi / Chưa) | B40: Chưa
A41: Bạn mang lại giá trị gì cho partner? | B41: Giúp VinFast chuẩn hóa quy trình tiếp nhận dịch vụ sau bán hàng của toàn bộ mạng lưới 400+ đại lý/xưởng dịch vụ, tăng tỷ lệ giữ chân khách hàng xe điện, giảm quá tải hotline tổng đài, và cung cấp dashboard thời gian thực đo lường chỉ số CSAT & tỷ lệ chuyển đổi dịch vụ.
A42: Nếu rơi vào vùng không khả thi — lối thoát nào? | B42: Nếu kênh Partner-Led bị chậm do thủ tục nội bộ VinFast, lối thoát dự phòng là chuyển sang Founder-Led Direct Sales tiếp cận trực tiếp 3–5 chủ đại lý 3S tư nhân lớn tại Hà Nội/TP.HCM (mô hình hybrid sales tập trung vào ROI ngắn hạn) trước khi ký phân phối toàn hệ thống. | D42: Giảm giá để tự phục vụ / tăng giá + service / Partner-Led

Sheet 5_90Day_Plan
A1: TAB 5 — PAIN MOMENT · 90-DAY PLAN · EVIDENCE PACK
A2: Trạm 5 và Trạm 6.
A4: A. PAIN MOMENT — phải đủ 3 phần
A5: MẤY GIỜ khách đau nhất? | B5: Thứ 7, từ 08h30 đến 10h30 sáng (khung giờ cao điểm khách hẹn xe cuối tuần)
A6: Lúc đó họ ĐANG LÀM GÌ? | B6: Nhân viên CSKH vừa nghe điện thoại tư vấn vừa mở phần mềm DMS tra slot kỹ thuật viên, trong khi 2 khách khác nhắn dồn dập trên Zalo OA hỏi lịch trống cuối tuần không được phản hồi kịp thời và thoát ra.
A7: Họ đang DÙNG APP / KÊNH NÀO? | B7: Zalo OA đại lý, Hotline điện thoại và phần mềm DMS
A8: → Điểm nhúng cụ thể của bạn | B8: Zalo Official Account (OA) Webhook & Facebook Messenger Fanpage của Đại lý, tích hợp trực tiếp 2 chiều qua API với DMS để kiểm tra và khóa slot kỹ thuật viên theo thời gian thực. | D8: Một bề mặt tích hợp có tên, không phải 'website của chúng tôi'
A10: B. 90-DAY PLAN
B11: THÁNG 1 — Học | C11: THÁNG 2–3 — Đòn bẩy | D11: THÁNG 4+ — Mở rộng
A12: Kênh sử dụng | B12: Founder-led Pilot trực tiếp | C12: Partner-Led (VinFast Aftersales) | D12: Mở rộng đại lý toàn quốc
A13: Mục tiêu số khách | B13: 2 đại lý 3S thí điểm | C13: 5 đại lý ủy quyền | D13: 15 đại lý mở rộng
A14: Việc cụ thể 1 | B14: Deploy chatbot Zalo OA cho 2 đại lý quen thuộc, theo dõi log từng booking | C14: Hoàn thiện Pilot Report có số liệu thực tế gửi Giám đốc Aftersales VinFast | D14: Đóng gói bộ cài đặt chuẩn (plug & play) kết nối DMS toàn bộ mạng lưới
A15: Việc cụ thể 2 | B15: Ngồi trực tiếp cùng nhân viên CSKH 2 buổi/tuần để ghi nhận edge case và bổ sung few-shot prompt | C15: Thuyết trình demo tại Hội nghị Giám đốc Dịch vụ Đại lý VinFast miền Bắc | D15: Tổ chức webinar đào tạo trực tuyến cho 50+ Trưởng xưởng dịch vụ
A16: Việc cụ thể 3 | B16: Đo lường containment rate thực tế trên 200 lượt booking đầu tiên và tối ưu cache | C16: Ký thỏa thuận đối tác giải pháp chính thức với bộ phận Aftersales VinFast | D16: Thiết lập kênh hỗ trợ kỹ thuật cấp 2 (L2 support) và cam kết SLA 99.9%
A17: KPI đo được | B17: 200 booking, CR ≥ 75%, 0 lỗi trùng lịch hẹn | C17: 5 đại lý active, 2.000 booking/tháng, GM ≥ 60% | D17: 15 đại lý, 6.000 booking/tháng, MRR > 140 triệu VNĐ
A18: Người chịu trách nhiệm | B18: Nguyễn Văn An (Founder / AI Lead) | C18: Nguyễn Văn An + Advisor quan hệ đối tác | D18: Nguyễn Văn An + Kỹ sư Triển khai (Deploy Engineer)
A19: Tháng 1 là giai đoạn HỌC, không phải scale. Kế hoạch 'tháng 1 lấy 200 khách ở 5 ngành' là kế hoạch chưa ai từng thử làm.
A21: C. EVIDENCE PACK — 3 tài sản bán hàng
A22: Tài sản | B22: Đã có? (Rồi/Chưa) | C22: Nội dung 1 câu — hoặc việc cần làm | D22: Người phụ trách · Deadline
A23: 1. Eval Results | B23: Chưa | C23: Eval trên 50 ca smoke test đạt CR 80%; cần chạy eval chuẩn hóa trên 200 ca thực tế đại lý (đo intent, slot accuracy, handoff rate). | D23: Nguyễn Văn An · 15/11/2026
A24: 2. Risk Checklist | B24: Rồi | C24: Đã hoàn thiện tài liệu giải trình 3 rủi ro: Anthropic API không train data, cơ chế fallback CSKH khi confidence < 85%, data xuất SQL độc lập trên Supabase. | D24: Nguyễn Văn An · 08/10/2026
A25: 3. Pilot Report | B25: Chưa | C25: Báo cáo kết quả thí điểm 4 tuần tại 2 đại lý: 200 booking, CR 80%, tiết kiệm 20h CSKH/tuần, tăng 15% booking dịch vụ ngoài giờ. | D25: Nguyễn Văn An · 30/11/2026
A26: Ô nào CHƯA CÓ thì ghi deadline — đừng bỏ trống. Thành thật về khoảng trống được điểm cao hơn bịa nội dung.
A28: D. BÀI TEST NGƯỜI LẠ — nhóm khác đọc One-Pager trong 2 phút
A29: Họ trả lời được: bán gì, cho ai, tính tiền theo đơn vị nào? (Được/Không) | B29: Được
A30: Họ trả lời được: có lãi trên mỗi đơn vị không, số nào chứng minh? (Được/Không) | B30: Được
A31: Họ trả lời được: tiếp cận khách qua đâu, vì sao kênh đó? (Được/Không) | B31: Được
A32: Số câu họ phải hỏi lại (mục tiêu ≤ 3) | B32: 1

Sheet 6_Benchmarks
A1: TAB 6 — BENCHMARKS (CHỈ ĐỌC)
A2: Giá chốt ngày 26/08/2026. Dòng có ⏳ là GIÁ KHUYẾN MẠI CÓ HẠN — phải kiểm tra lại.
A3: NGÀY BẠN KIỂM TRA LẠI GIÁ | B3: 08/10/2026 | D3: Bắt buộc điền — Rubric có chấm mục này
A5: Nhóm | B5: Mục | C5: Giá | D5: Đơn vị | E5: Nguồn
A6: LLM | B6: Claude Opus 5 — input / output | C6: 5,00 / 25,00 | D6: $ / 1M token | E6: platform.claude.com/docs/en/about-claude/pricing
A7: LLM | B7: Claude Sonnet 5 — input / output | C7: 2,00 / 10,00 | D7: $ / 1M token | E7: platform.claude.com/docs/en/about-claude/pricing
A8: LLM | B8: Claude Haiku 4.5 — input / output | C8: 1,00 / 5,00 | D8: $ / 1M token | E8: platform.claude.com/docs/en/about-claude/pricing
A9: LLM | B9: Claude — cache write 5' / cache read | C9: 1,25× / 0,10× input | D9: hệ số | E9: platform.claude.com/docs/en/about-claude/pricing
A10: LLM | B10: ⏳ OpenAI GPT-5.6 Sol — input / output | C10: 4,00 / 20,00 | D10: $ / 1M token | E10: developers.openai.com/api/docs/pricing (KM 21/08–21/11/2026; list 5,00/30,00)
A11: LLM | B11: OpenAI GPT-5.6 Luna — input / output | C11: 0,20 / 1,20 | D11: $ / 1M token | E11: developers.openai.com/api/docs/pricing
A12: LLM | B12: OpenAI — cached input / Batch API | C12: 10% input / −50% | D12: hệ số | E12: developers.openai.com/api/docs/pricing
A13: LLM | B13: Gemini 3.1 Pro — input / output (≤200k) | C13: 2,00 / 12,00 | D13: $ / 1M token | E13: ai.google.dev/gemini-api/docs/pricing
A14: LLM | B14: ⏳ Gemini 3.7 Flash — input / output | C14: 0,75 / 3,75 | D14: $ / 1M token | E14: ai.google.dev/gemini-api/docs/pricing (KM đến 31/12/2026; sau đó 1,50/7,50)
A15: STT | B15: Deepgram Nova-3 — pre-recorded | C15: 0,0043 | D15: $ / phút | E15: deepgram.com/pricing
A16: STT | B16: ⏳ Deepgram Nova-3 — streaming | C16: list 0,0077 · KM 0,0048 | D16: $ / phút | E16: deepgram.com/pricing — đang khuyến mại, kiểm tra lại
... A41: Benchmark | B41: ACV sàn cho inside sales | C41: ≈ 3.000 | D41: $ / năm | E41: Tomasz Tunguz (2016) — có kèm giả định để tính lại
A43: Lưu ý: trang marketing của nhà cung cấp có thể hiển thị giá cũ hơn trang docs. Ưu tiên trang docs / pricing chính thức.
